<?xml version="1.0"?>

<robot name="three_link_arm">

  <!-- Link 1 -->
  <link name="link1">
    <visual>
      <geometry>
        <box size="0.1 1 0.1"/>
      </geometry>
    </visual>
    <collision>
      <geometry>
        <box size="0.1 1 0.1"/>
      </geometry>
    </collision>
    <inertial>
      <mass value="1"/>
      <origin xyz="0 0 0"/>
      <inertia ixx="0.01" ixy="0" ixz="0" iyy="0.01" iyz="0" izz="0.01"/>
    </inertial>
  </link>

  <!-- Joint 1 -->
  <joint name="joint1" type="revolute">
    <parent link="world"/>
    <child link="link1"/>
    <origin xyz="0 0 0"/>
    <axis xyz="0 0 1"/>
    <limit effort="100" velocity="0.1" lower="-3.14159265359" upper="3.14159265359"/>
    <dynamics damping="0.0" friction="0.0"/>
  </joint>

  <!-- Link 2 -->
  <link name="link2">
    <visual>
      <geometry>
        <box size="0.1 1 0.1"/>
      </geometry>
    </visual>
    <collision>
      <geometry>
        <box size="0.1 1 0.1"/>
      </geometry>
    </collision>
    <inertial>
      <mass value="1"/>
      <origin xyz="1 0 0"/>
      <inertia ixx="0.01" ixy="0" ixz="0" iyy="0.01" iyz="0" izz="0.01"/>
    </inertial>
  </link>

  <!-- Joint 2 -->
  <joint name="joint2" type="revolute">
    <parent link="link1"/>
    <child link="link2"/>
    <origin xyz="1 0 0"/>
    <axis xyz="0 0 1"/>
    <limit effort="100" velocity="0.1" lower="-3.14159265359" upper="3.14159265359"/>
    <dynamics damping="0.0" friction="0.0"/>
  </joint>

  <!-- Link 3 -->
  <link name="link3">
    <visual>
      <geometry>
        <box size="0.1 1 0.1"/>
      </geometry>
    </visual>
    <collision>
      <geometry>
        <box size="0.1 1 0.1"/>
      </geometry>
    </collision>
    <inertial>
      <mass value="1"/>
      <origin xyz="2 0 0"/>
      <inertia ixx="0.01" ixy="0" ixz="0" iyy="0.01" iyz="0" izz="0.01"/>
    </inertial>
  </link>

  <!-- Joint 3 -->
  <joint name="joint3" type="revolute">
    <parent link="link2"/>
    <child link="link3"/>
    <origin xyz="2 0 0"/>
    <axis xyz="0 0 1"/>
    <limit effort="100" velocity="0.1" lower="-3.14159265359" upper="3.14159265359"/>
    <dynamics damping="0.0" friction="0.0"/>
  </joint>

</robot>
